Workbook

Sheet SUMMARY
A1: PURCHASES & EXPENSES 2026 — WORKBOOK SUMMARY
A2: Source file: purchase et expenses 2026 Bea.xlsx | Currency: RWF | All dates displayed as DD/MM/YYYY
A4: 1. WHAT THIS WORKBOOK CONTAINS
A5: Sheet | B5: Period covered | C5: Rows of data | D5: Status | E5: Contents
A6: JAN FEB MARC | B6: Jan–Mar 2026 | C6: 301 | D6: Complete | E6: Daily purchase/expense register + 3 monthly VAT blocks (sales, VAT recovered EBM, VAT sent, VAT to pay)
A7: APRIL, MAY JUN | B7: Apr–Jun 2026 | C7: 352 | D7: Complete | E7: Same structure as Q1: purchase register + 4 VAT computation blocks
A8: JULY AUG SEPT | B8: Jul–Sep 2026 | C8: 349 | D8: Repaired | E8: Purchase register + VAT blocks; 3 VAT-to-pay formulas were broken (#REF!) and have been rebuilt
A9: OCT NOV DEC | B9: Oct–Dec 2026 | C9: 0 | D9: EMPTY — to be filled | E9: Formatting only, no data yet. Q4 must be entered before the annual report is final
A10: ANNUAL REPORT | B10: Jan–Jun 2026 | C10: 170 | D10: Repaired | E10: Supplier-level purchase listing by month (TIN, supplier, goods, EBM receipt no., date, amount excl. VAT, VAT)
A11: IBIKENEWE MU KWIGA | B11: Requisition (dated 06/07/2025) | C11: 47 | D11: Repaired | E11: Requisition / stock roll-forward: qty x price, purchases, closing stock. 4 #VALUE! errors fixed
A12: control formule | B12: n/a | C12: 44 | D12: Working scratchpad | E12: Ad-hoc quantity x price checks and manual cross-checks; not part of the reporting chain
A13: UNCONTROLED | B13: Annual | C13: 9 | D13: Complete | E13: Uncontrolled / unsupported expense list (incl. an annualised 30,000 x 12 item)
A16: 2. PURCHASES & EXPENSES BY MONTH (from ANNUAL REPORT)
A17: Month | B17: Amount excl. VAT | C17: VAT | D17: Total incl. VAT | E17: Source cells
A18: January 2026 | B18: ='ANNUAL REPORT'!G39-C18 -> 17678888 | C18: =SUM('ANNUAL REPORT'!F1:F38) -> 890944 | D18: ='ANNUAL REPORT'!G39 -> 18569832 | E18: ANNUAL REPORT rows 1-39 (col G gross, col F VAT)
A19: February 2026 | B19: ='ANNUAL REPORT'!F48 -> 11564800 | C19: 0 | D19: =B19+C19 -> 11564800 | E19: ANNUAL REPORT F48 (no VAT recorded on these lines)
A20: March 2026 | B20: ='ANNUAL REPORT'!F59 -> 7065152.5 | C20: ='ANNUAL REPORT'!G54 -> 152847.46 | D20: =B20+C20 -> 7218000 | E20: ANNUAL REPORT F59 / G54
A21: April 2026 | B21: ='ANNUAL REPORT'!F86 -> 11872522 | C21: ='ANNUAL REPORT'!G74 -> 99696.97 | D21: =B21+C21 -> 11972219 | E21: ANNUAL REPORT F86 / G74
A22: May 2026 | B22: ='ANNUAL REPORT'!F121 -> 3516620.5 | C22: ='ANNUAL REPORT'!G114 -> 402609.59 | D22: =B22+C22 -> 3919230.1 | E22: ANNUAL REPORT F121 / G114
A23: June 2026 | B23: ='ANNUAL REPORT'!F170 -> 4406817.3 | C23: ='ANNUAL REPORT'!G157 -> 345905.4 | D23: =B23+C23 -> 4752722.7 | E23: ANNUAL REPORT F170 / G157
A24: TOTAL H1 2026 | B24: =SUM(B18:B23) -> 56104801 | C24: =SUM(C18:C23) -> 1892003.4 | D24: =SUM(D18:D23) -> 57996804 | E24: Jul-Dec 2026 not yet carried into ANNUAL REPORT
A27: 3. VAT DECLARATION BLOCKS (VAT recovered less VAT invoiced)
A28: Month labels beside these blocks are inconsistent in the source sheets — confirm the declaration period before filing.
A29: Sheet | B29: Block (source cell) | C29: VAT to pay / (credit) | E29: Note
A30: JAN FEB MARC | B30: Block 1 — G66 | C30: ='JAN FEB MARC'!G66 -> 24907 | E30: Labelled FEVRIER 2026 in source
A31: JAN FEB MARC | B31: Block 2 — G127 | C31: ='JAN FEB MARC'!G127 -> 66483 | E31: Labelled MARS 2026 in source
A32: JAN FEB MARC | B32: Block 3 — G175 | C32: ='JAN FEB MARC'!G175 -> -43481 | E32: Credit position (negative)
A33: APRIL, MAY JUN | B33: Block 1 — G55 | C33: ='APRIL, MAY JUN'!G55 -> -44966 | E33: Credit position (negative)
A34: APRIL, MAY JUN | B34: Block 2 — G109 | C34: ='APRIL, MAY JUN'!G109 -> -146503 | E34: Credit position (negative)
A35: APRIL, MAY JUN | B35: Block 3 — G179 | C35: ='APRIL, MAY JUN'!G179 -> -277473 | E35: Marked “REFUND JUNE” in source
A36: APRIL, MAY JUN | B36: Block 4 — G226 | C36: ='APRIL, MAY JUN'!G226 -> 3294175 | E36: Same sales/VAT figures as JULY AUG SEPT block 4 — possible duplicated block
A37: JULY AUG SEPT | B37: Block 1 — F55 | C37: ='JULY AUG SEPT '!F55 -> 154401 | E37: Intact in source
A38: JULY AUG SEPT | B38: Block 2 — F109 | C38: ='JULY AUG SEPT '!F109 -> 2943358.5 | E38: REBUILT (was #REF!) — VAT-recovered rows were blank; now derived from sales at 18/118
A39: JULY AUG SEPT | B39: Block 3 — F176 | C39: ='JULY AUG SEPT '!F176 -> 289793.53 | E39: REBUILT (was #REF!)
A40: JULY AUG SEPT | B40: Block 4 — F223 | C40: ='JULY AUG SEPT '!F223 -> 3294175.4 | E40: REBUILT (was #REF!)
A41: OCT NOV DEC | B41: — | C41: 0 | E41: Sheet is empty; no Q4 VAT blocks exist yet
A44: 4. AUDIT LOG — ISSUES FOUND
A45: Sheet | B45: Cells | C45: Severity | D45: Action | E45: Issue
A46: ANNUAL REPORT | B46: F59, F86, F121, F170 | C46: Critical | D46: FIXED | E46: Monthly totals summed a VAT subtotal line sitting in the Amount column — Mar/Apr/May/Jun were overstated by 152,847 / 99,697 / 402,610 / 345,905
A47: JULY AUG SEPT | B47: F109, F176, F223 (+F178) | C47: Critical | D47: FIXED | E47: VAT-to-pay formulas read =#REF!-... ; rebuilt as TOTAL VAT recovered less VAT invoiced, with D106/D107, D173/D174, D220/D221 derived from sales at 18/118
...

Sheet JAN FEB MARC
B2: JANVIER 2026
A3: date | B3: company tin | C3: company name | D3: items | E3: facture no | F3: vat sent | G3: total amount
A4: 46028 | C4: INNOPRO LTD | D4: SUGER | F4: 1037000 | G4: 6800000
A5: 46035 | C5: EASTERN HOPE SHOP LTD | D5: SUGER | F5: 1022034 | G5: 6700000
A6: 46044 | C6: HOZINEZA SHOP LTD | D6: SUGER | F6: 1000678 | G6: 6560000
A7: 46027 | C7: VPLUS PACKAGING INDUSTRIES LTD | D7: CARTONS | F7: 290395 | G7: 1903699
F8: =SUM(F4:F7) -> 3350107 | G8: =SUM(G4:G7) -> 21963699
B11: IZISIGAYE ZOSE NI DEPENSES
A13: 46039 | C13: PLAN ONE SUPPLY LTD | D13: IBIKORESHO BYO KUBAKA | F13: 508576 | G13: 3334000
A14: 46044 | C14: MINI IMPRIMERIES BLESSING | D14: PAPIER ENVELOPPES | F14: 62542 | G14: 410000 | H14: ISUKARI | I14: 6800000
A15: 46038 | C15: MINI IMPRIMERIES BLESSING | D15: PAPIER ENVELOPPES | F15: 46067 | G15: 302000 | I15: 6700000
A16: 46028 | C16: REG | D16: UMURIRO | E16: 50000 | F16: 30508 | G16: 200000 | I16: 6560000
A17: 45670 | C17: RIJE LTD | D17: DIFFERENT GOODS | F17: 25916 | G17: 200000 | H17: IBINYAMPEKE | I17: 2000000
A18: 46032 | C18: MINI IMPRIMERIES BLESSING | D18: PAPIER ENVELOPPES | F18: 22729 | G18: 149000 | I18: 4040000
A19: 46041 | C19: CPS LUBRICANT LTD | D19: HELIOS SAE | F19: 18305 | G19: 120000 | I19: 5200000
A20: 46027 | C20: AKOMBONYE COMPANY LTD | D20: WOODFIX | F20: 12600 | G20: 82600 | I20: 1435000
A21: 46050 | C21: CHAMPION TECHNOLOGIES LTD | D21: INK | F21: 1220 | G21: 8000 | I21: =SUM(I14:I20) -> 32735000
A22: 46042 | C22: IKAMBA GENERAL TRADING &SUPPLY CO LTD | D22: PRINT CERTIFICATES | F22: 6102 | G22: 40000 | H22: SALES | I22: =C60 -> 21984200
A23: 46050 | C23: REG | D23: UMURIRO | F23: 3043 | G23: 20000
A24: 46029 | C24: AGRUNI LTD | D24: WASTE COLLECTION SRV | G24: 24000 | H24: DIFFERENCE | I24: =I21-I22 -> 10750800
H25: IBITARACURUZWA
G27: =SUM(G13:G26) -> 4889600
A28: 46035 | C28: SP NYIRANGARAMA | D28: ESSANCES | F28: 11180 | G28: 73295
A29: 46043 | C29: SP NYIRANGARAMA | D29: ESSANCES | F29: 10825 | G29: 70968
A30: 46027 | B30: 103582274 | C30: SP NYIRANGARAMA | D30: ESSANCES | F30: 10312 | G30: 67606
A31: 46032 | C31: SP NYIRANGARAMA | D31: ESSANCES | F31: 9867 | G31: 64682
A32: 46037 | C32: SP NYIRANGARAMA | D32: ESSANCES | F32: 9660 | G32: 63330
A33: 46039 | C33: SP NYIRANGARAMA | D33: ESSANCES | F33: 9226 | G33: 60485
A34: 46049 | C34: SP NYIRANGARAMA | D34: ESSANCES | F34: 8428 | G34: 55254
A35: 46029 | C35: SP NYIRANGARAMA | D35: ESSANCES | F35: 8049 | G35: 52768
A36: 46028 | C36: SP NYIRANGARAMA | D36: ESSANCES | F36: 7958 | G36: 52171
A37: 46030 | C37: SP NYIRANGARAMA | D37: ESSANCES | F37: 7833 | G37: 51356
A38: 46034 | C38: SP NYIRANGARAMA | D38: ESSANCES | F38: 6899 | G38: 45230
A39: 46051 | C39: SP NYIRANGARAMA | D39: ESSANCES | F39: 6884 | G39: 45130
A40: 46025 | B40: 103582274 | C40: SP NYIRANGARAMA | D40: ESSANCES | F40: 6762 | G40: 44335
A41: 46039 | C41: SP NYIRANGARAMA | D41: ESSANCES | F41: 6733 | G41: 44136
A42: 46024 | B42: 103582274 | C42: SP NYIRANGARAMA | D42: ESSANCES | F42: 6374 | G42: 41769
A43: 46031 | C43: SP NYIRANGARAMA | D43: ESSANCES | F43: 5252 | G43: 34430
A44: 46037 | C44: SP NYIRANGARAMA | D44: ESSANCES | F44: 4575 | G44: 30000
A45: 46050 | C45: SP NYIRANGARAMA | D45: ESSANCES | F45: 4554 | G45: 29855
...

Sheet control formule
K2: AMADENI YO KURI TERRAIN RICHARD
J4: ITARIKI | K4: AHANTU | L4: AMAZINA | M4: IDENI
J5: 46031 | L5: JEANNETTE | M5: 435000
C6: manifesto | J6: 46032 | K6: KIGALI | L6: PETER DIDOS | M6: 15000
A7: 119 | B7: 14500 | C7: =A7*B7 -> 1725500 | E7: =C19 -> 1945500 | J7: 46070 | K7: MUSANZE | L7: CLARISSE | M7: 6500
A8: 0 | B8: 14500 | C8: =A8*B8 -> 0 | G8: depenses | J8: 46106 | L8: PAUL | M8: 15000 | N8: 46111
A9: 0 | B9: 15000 | C9: =A9*B9 -> 0 | E9: a verser | G9: 10500 | J9: 46112 | K9: MUSANZE | L9: CONSTANTIN | M9: 45000-32600 | N9: 46118
A10: 0 | B10: 6200 | C10: =A10*B10 -> 0 | E10: =E7-G16 -> 1401500 | G10: 26000 | J10: 46141 | K10: MUSANZE | L10: PAUL | M10: 90000
A11: 0 | B11: 6500 | C11: =A11*B11 -> 0 | F11: 0 | G11: 115500 | J11: 46090 | K11: KIGALI | L11: ROGER | M11: 145000-69000-45000-32500 | N11: 11/03,23/03,19/04/ | O11: RESTE 500
A12: 0 | B12: 4500 | C12: =A12*B12 -> 0 | E12: 632000 | G12: 296000 | J12: 46122 | K12: MUSANZE | L12: ERIC | M12: 30000-12000 | N12: 46134
A13: 0 | B13: 1208 | C13: =A13*B13 -> 0 | E13: 769500 | G13: 96000 | K13: MUSANZE | L13: JMV | M13: 14500
A14: 0 | B14: 2500 | C14: =A14*B14 -> 0 | E14: 0 | G14: 0 | J14: 46135 | K14: KIGALI | L14: THEONESTE | M14: 12000
A15: =SUM(A7:A14) -> 119 | C15: 60000 | E15: 0 | G15: 0 | J15: 46128 | K15: MUSANZE | L15: PETER | M15: 8000
C16: 72500 | D16: diff | E16: =E10-E12-E13-E14 -> 0 | G16: =SUM(G9:G15) -> 544000 | H16: 0 | J16: 46146 | K16: KIGALI | L16: FERDINAND/ KWISHYURA | M16: 30000
C17: 87500 | H17: =G16-H16 -> 544000 | J17: 46174 | L17: MOISE/ KWISHYURA | M17: 150000
C18: 0 | J18: 46148 | K18: GICUMBI | L18: JEANNETTE | M18: 19500
B19: ventes | C19: =SUM(C7:C18) -> 1945500 | J19: 46157 | K19: RUBAVU | L19: CLAUDE | M19: 300000-150000 | N19: 46164
J20: 46168 | K20: MUSANZE | L20: XAVIER | M20: 217500-130000 | N20: 46171
F21: 590000 | G21: 8800 | H21: =72*150 -> 10800 | J21: 46171 | K21: MUSANZE | L21: ANNANIAS | M21: 58500
F22: 662500 | G22: 9 | J22: 46171 | K22: KIGALI | L22: PAUL | M22: 140000-100000 | N22: 46175
F23: 0 | J23: 46174
F24: 0 | L24: ROGER | M24: 116000
F25: 0 | L25: NIYONSENGA | M25: 12500
F26: =SUM(F21:F25) -> 1252500
I29: 2026

Sheet IBIKENEWE MU KWIGA
B4: REQUISITION FORM
A5: DATE | B5: AMAZINA | C5: INGANO KG | D5: IGICIRO | E5: TOTAL | F5: IBYAGUZWE | G5: INGANO | H5: IBICIRO | I5: TOTAL | J5: IBISIGAYE | K5: INGANO | L5: IGICIRO | M5: TOTAL
A6: 45838 | B6: IBIGORI | C6: 3000 | D6: 500 | E6: =C6*D6 -> 1500000 | F6: IBIGORI | I6: =G6*H6 -> 0 | M6: =K6*L6 -> 0
B7: SOYA | C7: 600 | D7: 900 | E7: =C7*D7 -> 540000 | G7: =G6+E7-SUM(F7) -> 540000 | I7: =G7*H7 -> 0 | M7: =K7*L7 -> 0
B8: AMASAKA | C8: 2000 | D8: 650 | E8: =C8*D8 -> 1300000 | F8: AMASAKA | G8: 1600 | H8: 560 | I8: =G8*H8 -> 896000 | M8: =K8*L8 -> 0
B9: INGANO | C9: 500 | D9: 800 | E9: =C9*D9 -> 400000 | F9: INGANO | G9: =G8+E9-SUM(F9) -> 401600 | I9: =G9*H9 -> 0 | M9: =K9*L9 -> 0
B10: UBURO | C10: 500 | D10: 1400 | E10: =C10*D10 -> 700000 | F10: 0 | G10: =G9+E10-SUM(F10) -> 1101600 | I10: =G10*H10 -> 0 | M10: =K10*L10 -> 0
B11: SCOTCH | C11: 15 | D11: 30000 | E11: =D11*C11 -> 450000 | F11: SCOTCH | G11: 10 | H11: 30000 | I11: =G11*H11 -> 300000 | J11: INGANO | K11: 5 | L11: 30000 | M11: =K11*L11 -> 150000
B12: EMBALLAGE | C12: 25000 | D12: 20 | E12: =D12*C12 -> 500000 | I12: =G12*H12 -> 0 | M12: =K12*L12 -> 0
B13: WOODFIX | C13: 100 | D13: 2000 | E13: =D13*C13 -> 200000 | I13: =G13*H13 -> 0 | M13: =K13*L13 -> 0
B14: ISUKARI | C14: 200 | D14: 1600 | E14: =D14*C14 -> 320000 | I14: =G14*H14 -> 0 | M14: =K14*L14 -> 0
B15: AMATA | C15: 40 | D15: 12000 | E15: =D15*C15 -> 480000 | I15: =G15*H15 -> 0 | M15: =K15*L15 -> 0
I16: =G16*H16 -> 0 | M16: =K16*L16 -> 0
M17: =K17*L17 -> 0
E18: =C18*D18 -> 0 | G18: =G17+E18-F18 -> 0 | M18: =K18*L18 -> 0
E19: =C19*D19 -> 0 | G19: =G18+E19-F19 -> 0 | M19: =K19*L19 -> 0
E20: =C20*D20 -> 0 | G20: =G19+E20-F20 -> 0 | M20: =K20*L20 -> 0
E21: =C21*D21 -> 0 | G21: =G20+E21-F21 -> 0 | M21: =K21*L21 -> 0
E22: =SUM(E6:E21) -> 6390000

Sheet APRIL, MAY JUN
B2: AVRIL 2026
A3: date | B3: company tin | C3: company name | D3: items | E3: facture no | F3: vat sent | G3: total amount
A4: 46114 | B4: 103346025 | C4: RIJE LTD | D4: DIFFERENT GOOD | F4: 25627 | G4: 340800
A5: 46114 | C5: FIVE STARSINVESTMENT LTD | D5: SUGER | F5: 983898 | G5: 6450000
A6: 46114 | C6: MINI IMPRIMERIE BLESSING | D6: PAPIER ENVELOPPE | F6: 63457 | G6: 416000
A7: 46116 | C7: QUINCAILLERIE REMARKABLE CO LTD | D7: AKAYUNGIRIZO | F7: 7337 | G7: 48100
A8: 46115 | C8: SP NYIRANGARAMA | D8: ESSANCES | F8: 3052 | G8: 20000
A9: 46115 | C9: SP NYIRANGARAMA | D9: ESSANCES | F9: 8319 | G9: 54538
A10: 46114 | C10: SP NYIRANGARAMA | D10: ESSANCES | F10: 10822 | G10: 70948
A11: 46114 | C11: SP NYIRANGARAMA | D11: ESSANCES | F11: 2311 | G11: 15156
A12: 46113 | C12: SP NYIRANGARAMA | D12: ESSANCES | F12: 3331 | G12: 21838
A13: 46116 | C13: MOUNT MERU PETROLEUM LTD | D13: ESSANCES | F13: 11224 | G13: 73581
A14: 46118 | C14: SP NYIRANGARAMA | D14: ESSANCES | F14: 5037 | G14: 33025 | H14: ISUKARI | I14: 6450000
A15: 46118 | C15: SP NYIRANGARAMA | D15: ESSANCES | F15: 664 | G15: 43688 | I15: 6600000
A16: 46120 | C16: AGRI SOKONI | D16: MAIZE SCREEN | F16: 12203 | G16: 80000 | I16: 3075000
A17: 46118 | C17: POLYBAGS RWANDA | D17: PRINTED BAGS | F17: 24406 | G17: 160000 | H17: IBINYAMPEKE | I17: 275225
A18: 46121 | C18: SP NYIRANGARAMA | D18: ESSANCES | F18: 13451 | G18: 88182 | I18: 913200
A19: 46126 | C19: WELLARS SUPPLY LTD | D19: LUGAZ SUGER | F19: 1006780 | G19: 6600000 | I19: 2300000
A20: 46125 | C20: TERRAZZO LTD | D20: TILES | F20: 8237 | G20: 54000
A21: 46126 | C21: SP NYIRANGARAMA | D21: ESSANCES | F21: 7655 | G21: 50182 | I21: =SUM(I14:I20) -> 19613425
A22: 46122 | C22: SP NYIRANGARAMA | D22: ESSANCES | F22: 11586 | G22: 75953 | H22: SALES | I22: =C49 -> 20459250
A23: 46125 | C23: SP NYIRANGARAMA | D23: ESSANCES | F23: 13118 | G23: 85994
A24: 46125 | C24: VPLUS PACKAGING INDUSTRIES LTD | D24: CARTONS | F24: 273288 | G24: 1791552 | H24: DIFFERENCE | I24: =I21-I22 -> -845825
A25: 46129 | C25: SP NYIRANGARAMA | D25: ESSANCES | F25: 11621 | G25: 76182 | H25: IBITARACURUZWA
A26: 46128 | C26: SP NYIRANGARAMA | D26: ESSANCES | F26: 12028 | G26: 78855
A27: 46121 | C27: SP NYIRANGARAMA | D27: ESSANCES | F27: 4145 | G27: 27175
A28: 46134 | C28: SP NYIRANGARAMA | D28: ESSANCES | F28: 5899 | G28: 38664
A29: 46133 | C29: SP NYIRANGARAMA | D29: ESSANCES | F29: 11105 | G29: 72804
A30: 46135 | C30: SP NYIRANGARAMA | D30: ESSANCES | F30: 4436 | G30: 29086
A31: 46131 | C31: SP NYIRANGARAMA | D31: ESSANCES | F31: 13297 | G31: 87170
A32: 46135 | C32: MINI IMPRIMERIE BLESSING | D32: PAPIER ENVELOPPE | F32: 64067 | G32: 420000
A33: 46120 | C33: COWBE LTD | D33: WATER | F33: 979 | G33: 6422
C34: REG | D34: UMURIRO | F34: 30508 | G34: 200000
A35: 46136 | C35: SP NYIRANGARAMA | D35: ESSANCES | F35: 4100 | G35: 26883
A36: 46139 | C36: MOUNT MERU PETROLEUM LTD | D36: ESSANCES | F36: 18913 | G36: 123984
A37: 46140 | C37: INNOPRO LTD | D37: SUGER | F37: 469068 | G37: 3075000
A38: 46141 | C38: SP NYIRANGARAMA | D38: ESSANCES | F38: 9120 | G38: 59788
A39: 46141 | C39: SP NYIRANGARAMA | D39: ESSANCES | F39: 3809 | G39: 24973
A41: 46121 | C41: NTAGANDA ERASTE | D41: DRIED SORGHUM | G41: 275225
A42: 46122 | C42: HANOCLANO | D42: SORGHUM | G42: =1522*600 -> 913200
...

Sheet JULY AUG SEPT 
B2: 46204
A3: date | B3: company tin | C3: company name | D3: items | E3: vat sent | F3: total amount
A4: 46205 | C4: VPLUS PACKAGING INDUSTRIES LTD | D4: CARTONS | E4: 277030 | F4: 1816084
A5: 46204 | C5: SP NYIRANGARAMA | D5: ESSANCES | E5: 16277 | F5: 106708
A6: 46205 | C6: SP NYIRANGARAMA | D6: ESSANCES | E6: 4576 | F6: 30000
A7: 46206 | C7: PEACE H TRADING COMPANY LTD | D7: COLLE WOODFIX | E7: 15254 | F7: 100000
A8: 46206 | C8: SP NYIRANGARAMA | D8: ESSANCES | E8: 16736 | F8: 109705
A9: 46209 | C9: SP NYIRANGARAMA | D9: ESSANCES | E9: 14270 | F9: 93546
A10: 46210 | C10: SP NYIRANGARAMA | D10: ESSANCES | E10: 15309 | F10: 100362
A11: 46214 | C11: MOUNT MERU PETROLEUM | D11: ESSANCES | E11: 6973 | F11: 45715
A12: 46213 | C12: SP NYIRANGARAMA | D12: ESSANCES | E12: 15968 | F12: 104681
A13: 46210 | C13: POLYBAGS RWANDA LTD | D13: BAGS | E13: 28220 | F13: 185000
A14: 46216 | C14: GILGAL LTD | D14: BANDEFREI | E14: 7780 | F14: 51000
A15: 46216 | C15: SP NYIRANGARAMA | D15: ESSANCES | E15: 9618 | F15: 63049
... A26: 46217 | C26: BFBMS LTD | D26: BRAKE PAD | E26: 3050 | F26: 20000
A32: 46206 | C32: PRODEV RWANDA LTD | D32: LAYERS MASH | F32: 116000
A33: 46210 | C33: PRODEV RWANDA LTD | D33: LAYERS MASH | F33: 78500
A34: 46207 | C34: NTAGANDA ERASTE | D34: SORGHUM | F34: 748410
A35: 46216 | C35: NTAGANDA ERASTE | D35: SORGHUM | F35: 571155
A36: 46213 | C36: PRODEV RWANDA LTD | D36: LAYERS MASH | F36: 116000
A37: 46217 | C37: PRODEV RWANDA LTD | D37: GROWER MASH | F37: 37500
E46: =SUM(E4:E40) -> 1488556
B47: SALES BRANCH 01 | D47: 10198500 | E47: =D47*18/118 -> 1555703.4
B48: SALES BASE | D48: 572000 | E48: =D48*18/118 -> 87254.237
C49: =D47+D48 -> 10770500 | E49: =D49*18/118 -> 0
B50: VAT MANAGEMENT | E50: VAT SENT FACT | F50: VAT TO PAY
B52: VAT BRANCH01 REC | D52: 1555703
B53: VAT BASE REC | D53: 87254
B55: TOTAL | D55: =SUM(D52:D54) -> 1642957 | E55: =E46 -> 1488556 | F55: =D55-E55 -> 154401 | H55: AYISHYURWA
F56: WORD | H56: BURI KWEZI
B57: FACTURE ZIKENEWE | D57: =F55*118/18 -> 1012184.3
C61: MAI 2026
A62: date | B62: company tin | C62: company name | D62: items | E62: vat sent | F62: total amount
H68: =E67-E68 -> 0
A90: IBINYAMPEKE BIDAFITE VAT
B101: SALES BRANCH 01 | D101: 18429550 | G101: STOCK
B102: SALES BASE | D102: 865800 | E102: 0
C103: =D101+D102 -> 19295350 | D103: 180900 | E103: =E67 -> 0
B104: VAT MANAGEMENT | E104: VAT SENT FACT | F104: VAT TO PAY | I104: =G106-E109 -> 3483853
B106: VAT BRANCH01 REC | D106: =D101*18/118 -> 2811287.3 | G106: 3483853
...

Sheet OCT NOV DEC

Sheet ANNUAL REPORT
A1: 46039 | C1: PLAN ONE SUPPLY LTD | D1: IBIKORESHO BYO KUBAKA | F1: 508576 | G1: 3334000
A2: 46044 | C2: MINI IMPRIMERIES BLESSING | D2: PAPIER ENVELOPPES | F2: 62542 | G2: 410000
A3: 46038 | C3: MINI IMPRIMERIES BLESSING | D3: PAPIER ENVELOPPES | F3: 46067 | G3: 302000
A4: 46028 | C4: REG | D4: UMURIRO | E4: 50000 | F4: 30508 | G4: 200000
A5: 45670 | C5: RIJE LTD | D5: DIFFERENT GOODS | F5: 25916 | G5: 200000
A6: 46032 | C6: MINI IMPRIMERIES BLESSING | D6: PAPIER ENVELOPPES | F6: 22729 | G6: 149000
A7: 46041 | C7: CPS LUBRICANT LTD | D7: HELIOS SAE | F7: 18305 | G7: 120000
A8: 46027 | C8: AKOMBONYE COMPANY LTD | D8: WOODFIX | F8: 12600 | G8: 82600
A9: 46050 | C9: CHAMPION TECHNOLOGIES LTD | D9: INK | F9: 1220 | G9: 8000
A10: 46042 | C10: IKAMBA GENERAL TRADING &SUPPLY CO LTD | D10: PRINT CERTIFICATES | F10: 6102 | G10: 40000
A11: 46050 | C11: REG | D11: UMURIRO | F11: 3043 | G11: 20000
A12: 46029 | C12: AGRUNI LTD | D12: WASTE COLLECTION SRV | G12: 24000
A13: 46035 | C13: SP NYIRANGARAMA | D13: ESSANCES | F13: 11180 | G13: 73295
A14: 46043 | C14: SP NYIRANGARAMA | D14: ESSANCES | F14: 10825 | G14: 70968
A15: 46027 | B15: 103582274 | C15: SP NYIRANGARAMA | D15: ESSANCES | F15: 10312 | G15: 67606
A16: 46032 | C16: SP NYIRANGARAMA | D16: ESSANCES | F16: 9867 | G16: 64682
A17: 46037 | C17: SP NYIRANGARAMA | D17: ESSANCES | F17: 9660 | G17: 63330
A18: 46039 | C18: SP NYIRANGARAMA | D18: ESSANCES | F18: 9226 | G18: 60485
A19: 46049 | C19: SP NYIRANGARAMA | D19: ESSANCES | F19: 8428 | G19: 55254
A20: 46029 | C20: SP NYIRANGARAMA | D20: ESSANCES | F20: 8049 | G20: 52768
A21: 46028 | C21: SP NYIRANGARAMA | D21: ESSANCES | F21: 7958 | G21: 52171
A22: 46030 | C22: SP NYIRANGARAMA | D22: ESSANCES | F22: 7833 | G22: 51356
A23: 46034 | C23: SP NYIRANGARAMA | D23: ESSANCES | F23: 6899 | G23: 45230
A24: 46051 | C24: SP NYIRANGARAMA | D24: ESSANCES | F24: 6884 | G24: 45130
A25: 46025 | B25: 103582274 | C25: SP NYIRANGARAMA | D25: ESSANCES | F25: 6762 | G25: 44335
A26: 46039 | C26: SP NYIRANGARAMA | D26: ESSANCES | F26: 6733 | G26: 44136
A27: 46024 | B27: 103582274 | C27: SP NYIRANGARAMA | D27: ESSANCES | F27: 6374 | G27: 41769
A28: 46031 | C28: SP NYIRANGARAMA | D28: ESSANCES | F28: 5252 | G28: 34430
A29: 46037 | C29: SP NYIRANGARAMA | D29: ESSANCES | F29: 4575 | G29: 30000
A30: 46050 | C30: SP NYIRANGARAMA | D30: ESSANCES | F30: 4554 | G30: 29855
A31: 46050 | C31: SP NYIRANGARAMA | D31: ESSANCES | F31: 4554 | G31: 29855
A32: 46034 | C32: SP NYIRANGARAMA | D32: ESSANCES | F32: 3052 | G32: 20000
A33: 46040 | C33: SP NYIRANGARAMA | D33: ESSANCES | F33: 2833 | G33: 18577
A34: 46036 | C34: SP NYIRANGARAMA | D34: ESSANCES | F34: 1526 | G34: 10000
A35: 46030 | C35: BATTISTA BUSINESS | D35: IBIGORI | G35: 4040000
A36: 46043 | C36: BATTISTA BUSINESS | D36: SOYA NÍBIGORI | G36: 5200000
A37: 46043 | C37: GACAMUMANZA | D37: IBIGORI | G37: 1435000
A38: 46029 | C38: MAGENDU PONTIEN | D38: IBIGORI | G38: 2000000
G39: =SUM(G1:G38) -> 18569832
B40: IZISIGAYE FEVRUARY 2026
...

Sheet UNCONTROLED 
B4: 1 | C4: INYUNGU KU NGUZANYO
B5: 2 | C5: DEPENSES Z
B6: 3 | C6: DEPRECIATION IMODOKA NA MACHINE
B7: 4 | C7: UBUKODE BW'INZU | D7: =30000*12 -> 360000
B8: 5 | C8: PARKING YÍMODOKA MU MUJYI
B9: 6 | C9: GUKANIKA IMODOKA
B10: 7 | C10: GUHAHA IBIRIBWA BYÁBAKOZI (IBITOKI, IBIRAYI, AMASHU, AMATA, IMYUMBATI, AMATEKE, INKA, IHENE, INGURUBE, INTAMA,
B11: 8 | C11: GUHAHA INKA,
B12: 9 | C12: UMUTEKANO
